2018-11-06 19:25:57,493 ERROR: Exception on /_process [POST] [in /Users/timc/PycharmProjects/SAAC/venv/lib/python3.7/site-packages/flask/app.py:1761]
Traceback (most recent call last):
  File "/Users/timc/PycharmProjects/SAAC/venv/lib/python3.7/site-packages/flask/app.py", line 2292, in wsgi_app
    response = self.full_dispatch_request()
  File "/Users/timc/PycharmProjects/SAAC/venv/lib/python3.7/site-packages/flask/app.py", line 1815, in full_dispatch_request
    rv = self.handle_user_exception(e)
  File "/Users/timc/PycharmProjects/SAAC/venv/lib/python3.7/site-packages/flask/app.py", line 1718, in handle_user_exception
    reraise(exc_type, exc_value, tb)
  File "/Users/timc/PycharmProjects/SAAC/venv/lib/python3.7/site-packages/flask/_compat.py", line 35, in reraise
    raise value
  File "/Users/timc/PycharmProjects/SAAC/venv/lib/python3.7/site-packages/flask/app.py", line 1813, in full_dispatch_request
    rv = self.dispatch_request()
  File "/Users/timc/PycharmProjects/SAAC/venv/lib/python3.7/site-packages/flask/app.py", line 1799, in dispatch_request
    return self.view_functions[rule.endpoint](**req.view_args)
  File "/Users/timc/PycharmProjects/SAAC/app/routes.py", line 191, in process
    process_expertise_change(inputs)
  File "/Users/timc/PycharmProjects/SAAC/app/services.py", line 38, in process_expertise_change
    s.population += 1
AttributeError: 'Expertise' object has no attribute 'population'
2018-11-06 19:25:58,739 ERROR: Exception on /_process [POST] [in /Users/timc/PycharmProjects/SAAC/venv/lib/python3.7/site-packages/flask/app.py:1761]
Traceback (most recent call last):
  File "/Users/timc/PycharmProjects/SAAC/venv/lib/python3.7/site-packages/flask/app.py", line 2292, in wsgi_app
    response = self.full_dispatch_request()
  File "/Users/timc/PycharmProjects/SAAC/venv/lib/python3.7/site-packages/flask/app.py", line 1815, in full_dispatch_request
    rv = self.handle_user_exception(e)
  File "/Users/timc/PycharmProjects/SAAC/venv/lib/python3.7/site-packages/flask/app.py", line 1718, in handle_user_exception
    reraise(exc_type, exc_value, tb)
  File "/Users/timc/PycharmProjects/SAAC/venv/lib/python3.7/site-packages/flask/_compat.py", line 35, in reraise
    raise value
  File "/Users/timc/PycharmProjects/SAAC/venv/lib/python3.7/site-packages/flask/app.py", line 1813, in full_dispatch_request
    rv = self.dispatch_request()
  File "/Users/timc/PycharmProjects/SAAC/venv/lib/python3.7/site-packages/flask/app.py", line 1799, in dispatch_request
    return self.view_functions[rule.endpoint](**req.view_args)
  File "/Users/timc/PycharmProjects/SAAC/app/routes.py", line 191, in process
    process_expertise_change(inputs)
  File "/Users/timc/PycharmProjects/SAAC/app/services.py", line 38, in process_expertise_change
    s.population += 1
AttributeError: 'Expertise' object has no attribute 'population'
2018-11-06 19:25:59,323 ERROR: Exception on /_process [POST] [in /Users/timc/PycharmProjects/SAAC/venv/lib/python3.7/site-packages/flask/app.py:1761]
Traceback (most recent call last):
  File "/Users/timc/PycharmProjects/SAAC/venv/lib/python3.7/site-packages/flask/app.py", line 2292, in wsgi_app
    response = self.full_dispatch_request()
  File "/Users/timc/PycharmProjects/SAAC/venv/lib/python3.7/site-packages/flask/app.py", line 1815, in full_dispatch_request
    rv = self.handle_user_exception(e)
  File "/Users/timc/PycharmProjects/SAAC/venv/lib/python3.7/site-packages/flask/app.py", line 1718, in handle_user_exception
    reraise(exc_type, exc_value, tb)
  File "/Users/timc/PycharmProjects/SAAC/venv/lib/python3.7/site-packages/flask/_compat.py", line 35, in reraise
    raise value
  File "/Users/timc/PycharmProjects/SAAC/venv/lib/python3.7/site-packages/flask/app.py", line 1813, in full_dispatch_request
    rv = self.dispatch_request()
  File "/Users/timc/PycharmProjects/SAAC/venv/lib/python3.7/site-packages/flask/app.py", line 1799, in dispatch_request
    return self.view_functions[rule.endpoint](**req.view_args)
  File "/Users/timc/PycharmProjects/SAAC/app/routes.py", line 191, in process
    process_expertise_change(inputs)
  File "/Users/timc/PycharmProjects/SAAC/app/services.py", line 38, in process_expertise_change
    s.population += 1
AttributeError: 'Expertise' object has no attribute 'population'
2018-11-06 19:25:59,778 ERROR: Exception on /_process [POST] [in /Users/timc/PycharmProjects/SAAC/venv/lib/python3.7/site-packages/flask/app.py:1761]
Traceback (most recent call last):
  File "/Users/timc/PycharmProjects/SAAC/venv/lib/python3.7/site-packages/flask/app.py", line 2292, in wsgi_app
    response = self.full_dispatch_request()
  File "/Users/timc/PycharmProjects/SAAC/venv/lib/python3.7/site-packages/flask/app.py", line 1815, in full_dispatch_request
    rv = self.handle_user_exception(e)
  File "/Users/timc/PycharmProjects/SAAC/venv/lib/python3.7/site-packages/flask/app.py", line 1718, in handle_user_exception
    reraise(exc_type, exc_value, tb)
  File "/Users/timc/PycharmProjects/SAAC/venv/lib/python3.7/site-packages/flask/_compat.py", line 35, in reraise
    raise value
  File "/Users/timc/PycharmProjects/SAAC/venv/lib/python3.7/site-packages/flask/app.py", line 1813, in full_dispatch_request
    rv = self.dispatch_request()
  File "/Users/timc/PycharmProjects/SAAC/venv/lib/python3.7/site-packages/flask/app.py", line 1799, in dispatch_request
    return self.view_functions[rule.endpoint](**req.view_args)
  File "/Users/timc/PycharmProjects/SAAC/app/routes.py", line 191, in process
    process_expertise_change(inputs)
  File "/Users/timc/PycharmProjects/SAAC/app/services.py", line 38, in process_expertise_change
    s.population += 1
AttributeError: 'Expertise' object has no attribute 'population'
2018-11-06 19:26:00,219 ERROR: Exception on /_process [POST] [in /Users/timc/PycharmProjects/SAAC/venv/lib/python3.7/site-packages/flask/app.py:1761]
Traceback (most recent call last):
  File "/Users/timc/PycharmProjects/SAAC/venv/lib/python3.7/site-packages/flask/app.py", line 2292, in wsgi_app
    response = self.full_dispatch_request()
  File "/Users/timc/PycharmProjects/SAAC/venv/lib/python3.7/site-packages/flask/app.py", line 1815, in full_dispatch_request
    rv = self.handle_user_exception(e)
  File "/Users/timc/PycharmProjects/SAAC/venv/lib/python3.7/site-packages/flask/app.py", line 1718, in handle_user_exception
    reraise(exc_type, exc_value, tb)
  File "/Users/timc/PycharmProjects/SAAC/venv/lib/python3.7/site-packages/flask/_compat.py", line 35, in reraise
    raise value
  File "/Users/timc/PycharmProjects/SAAC/venv/lib/python3.7/site-packages/flask/app.py", line 1813, in full_dispatch_request
    rv = self.dispatch_request()
  File "/Users/timc/PycharmProjects/SAAC/venv/lib/python3.7/site-packages/flask/app.py", line 1799, in dispatch_request
    return self.view_functions[rule.endpoint](**req.view_args)
  File "/Users/timc/PycharmProjects/SAAC/app/routes.py", line 191, in process
    process_expertise_change(inputs)
  File "/Users/timc/PycharmProjects/SAAC/app/services.py", line 38, in process_expertise_change
    s.population += 1
AttributeError: 'Expertise' object has no attribute 'population'
2018-11-06 19:26:01,577 ERROR: Exception on /_process [POST] [in /Users/timc/PycharmProjects/SAAC/venv/lib/python3.7/site-packages/flask/app.py:1761]
Traceback (most recent call last):
  File "/Users/timc/PycharmProjects/SAAC/venv/lib/python3.7/site-packages/flask/app.py", line 2292, in wsgi_app
    response = self.full_dispatch_request()
  File "/Users/timc/PycharmProjects/SAAC/venv/lib/python3.7/site-packages/flask/app.py", line 1815, in full_dispatch_request
    rv = self.handle_user_exception(e)
  File "/Users/timc/PycharmProjects/SAAC/venv/lib/python3.7/site-packages/flask/app.py", line 1718, in handle_user_exception
    reraise(exc_type, exc_value, tb)
  File "/Users/timc/PycharmProjects/SAAC/venv/lib/python3.7/site-packages/flask/_compat.py", line 35, in reraise
    raise value
  File "/Users/timc/PycharmProjects/SAAC/venv/lib/python3.7/site-packages/flask/app.py", line 1813, in full_dispatch_request
    rv = self.dispatch_request()
  File "/Users/timc/PycharmProjects/SAAC/venv/lib/python3.7/site-packages/flask/app.py", line 1799, in dispatch_request
    return self.view_functions[rule.endpoint](**req.view_args)
  File "/Users/timc/PycharmProjects/SAAC/app/routes.py", line 191, in process
    process_expertise_change(inputs)
  File "/Users/timc/PycharmProjects/SAAC/app/services.py", line 38, in process_expertise_change
    s.population += 1
AttributeError: 'Expertise' object has no attribute 'population'
2018-11-06 19:26:36,355 INFO: Microblog startup [in /Users/timc/PycharmProjects/SAAC/app/__init__.py:47]
2018-11-06 19:27:19,351 INFO: Microblog startup [in /Users/timc/PycharmProjects/SAAC/app/__init__.py:47]
2018-11-06 19:27:39,782 INFO: Microblog startup [in /Users/timc/PycharmProjects/SAAC/app/__init__.py:47]
