2018-10-12 17:20:16,355 INFO: Microblog startup [in /Users/timc/PycharmProjects/SAAC/app/__init__.py:45]
2018-10-12 17:30:22,916 INFO: Microblog startup [in /Users/timc/PycharmProjects/SAAC/app/__init__.py:45]
2018-10-12 17:33:38,035 INFO: Microblog startup [in /Users/timc/PycharmProjects/SAAC/app/__init__.py:45]
2018-10-12 17:36:47,480 INFO: Microblog startup [in /Users/timc/PycharmProjects/SAAC/app/__init__.py:45]
2018-10-12 17:49:27,093 INFO: Microblog startup [in /Users/timc/PycharmProjects/SAAC/app/__init__.py:45]
2018-10-12 17:50:27,293 INFO: Microblog startup [in /Users/timc/PycharmProjects/SAAC/app/__init__.py:45]
2018-10-12 17:51:02,311 INFO: Microblog startup [in /Users/timc/PycharmProjects/SAAC/app/__init__.py:45]
2018-10-12 17:57:10,959 INFO: Microblog startup [in /Users/timc/PycharmProjects/SAAC/app/__init__.py:45]
2018-10-12 17:58:00,577 INFO: Microblog startup [in /Users/timc/PycharmProjects/SAAC/app/__init__.py:45]
2018-10-12 17:59:41,243 INFO: Microblog startup [in /Users/timc/PycharmProjects/SAAC/app/__init__.py:45]
2018-10-12 17:59:55,737 INFO: Microblog startup [in /Users/timc/PycharmProjects/SAAC/app/__init__.py:45]
2018-10-12 18:01:41,304 INFO: Microblog startup [in /Users/timc/PycharmProjects/SAAC/app/__init__.py:45]
2018-10-12 18:18:15,295 INFO: Microblog startup [in /Users/timc/PycharmProjects/SAAC/app/__init__.py:45]
2018-10-12 18:18:43,714 INFO: Microblog startup [in /Users/timc/PycharmProjects/SAAC/app/__init__.py:45]
2018-10-12 18:19:17,201 INFO: Microblog startup [in /Users/timc/PycharmProjects/SAAC/app/__init__.py:45]
2018-10-12 18:20:05,910 INFO: Microblog startup [in /Users/timc/PycharmProjects/SAAC/app/__init__.py:45]
2018-10-13 18:14:06,262 INFO: Microblog startup [in /Users/timc/PycharmProjects/SAAC/app/__init__.py:45]
2018-10-13 18:18:40,004 INFO: Microblog startup [in /Users/timc/PycharmProjects/SAAC/app/__init__.py:45]
2018-10-13 18:18:52,201 ERROR: Exception on /_removePost [POST] [in /Users/timc/PycharmProjects/SAAC/venv/lib/python3.7/site-packages/flask/app.py:1761]
Traceback (most recent call last):
  File "/Users/timc/PycharmProjects/SAAC/venv/lib/python3.7/site-packages/sqlalchemy/engine/base.py", line 1193, in _execute_context
    context)
  File "/Users/timc/PycharmProjects/SAAC/venv/lib/python3.7/site-packages/sqlalchemy/engine/default.py", line 509, in do_execute
    cursor.execute(statement, parameters)
sqlite3.OperationalError: database is locked

The above exception was the direct cause of the following exception:

Traceback (most recent call last):
  File "/Users/timc/PycharmProjects/SAAC/venv/lib/python3.7/site-packages/flask/app.py", line 2292, in wsgi_app
    response = self.full_dispatch_request()
  File "/Users/timc/PycharmProjects/SAAC/venv/lib/python3.7/site-packages/flask/app.py", line 1815, in full_dispatch_request
    rv = self.handle_user_exception(e)
  File "/Users/timc/PycharmProjects/SAAC/venv/lib/python3.7/site-packages/flask/app.py", line 1718, in handle_user_exception
    reraise(exc_type, exc_value, tb)
  File "/Users/timc/PycharmProjects/SAAC/venv/lib/python3.7/site-packages/flask/_compat.py", line 35, in reraise
    raise value
  File "/Users/timc/PycharmProjects/SAAC/venv/lib/python3.7/site-packages/flask/app.py", line 1813, in full_dispatch_request
    rv = self.dispatch_request()
  File "/Users/timc/PycharmProjects/SAAC/venv/lib/python3.7/site-packages/flask/app.py", line 1799, in dispatch_request
    return self.view_functions[rule.endpoint](**req.view_args)
  File "/Users/timc/PycharmProjects/SAAC/app/routes.py", line 88, in remove_post
    db.session.commit()
  File "/Users/timc/PycharmProjects/SAAC/venv/lib/python3.7/site-packages/sqlalchemy/orm/scoping.py", line 153, in do
    return getattr(self.registry(), name)(*args, **kwargs)
  File "/Users/timc/PycharmProjects/SAAC/venv/lib/python3.7/site-packages/sqlalchemy/orm/session.py", line 943, in commit
    self.transaction.commit()
  File "/Users/timc/PycharmProjects/SAAC/venv/lib/python3.7/site-packages/sqlalchemy/orm/session.py", line 467, in commit
    self._prepare_impl()
  File "/Users/timc/PycharmProjects/SAAC/venv/lib/python3.7/site-packages/sqlalchemy/orm/session.py", line 447, in _prepare_impl
    self.session.flush()
  File "/Users/timc/PycharmProjects/SAAC/venv/lib/python3.7/site-packages/sqlalchemy/orm/session.py", line 2254, in flush
    self._flush(objects)
  File "/Users/timc/PycharmProjects/SAAC/venv/lib/python3.7/site-packages/sqlalchemy/orm/session.py", line 2380, in _flush
    transaction.rollback(_capture_exception=True)
  File "/Users/timc/PycharmProjects/SAAC/venv/lib/python3.7/site-packages/sqlalchemy/util/langhelpers.py", line 66, in __exit__
    compat.reraise(exc_type, exc_value, exc_tb)
  File "/Users/timc/PycharmProjects/SAAC/venv/lib/python3.7/site-packages/sqlalchemy/util/compat.py", line 249, in reraise
    raise value
  File "/Users/timc/PycharmProjects/SAAC/venv/lib/python3.7/site-packages/sqlalchemy/orm/session.py", line 2344, in _flush
    flush_context.execute()
  File "/Users/timc/PycharmProjects/SAAC/venv/lib/python3.7/site-packages/sqlalchemy/orm/unitofwork.py", line 391, in execute
    rec.execute(self)
  File "/Users/timc/PycharmProjects/SAAC/venv/lib/python3.7/site-packages/sqlalchemy/orm/unitofwork.py", line 556, in execute
    uow
  File "/Users/timc/PycharmProjects/SAAC/venv/lib/python3.7/site-packages/sqlalchemy/orm/persistence.py", line 177, in save_obj
    mapper, table, update)
  File "/Users/timc/PycharmProjects/SAAC/venv/lib/python3.7/site-packages/sqlalchemy/orm/persistence.py", line 768, in _emit_update_statements
    execute(statement, multiparams)
  File "/Users/timc/PycharmProjects/SAAC/venv/lib/python3.7/site-packages/sqlalchemy/engine/base.py", line 948, in execute
    return meth(self, multiparams, params)
  File "/Users/timc/PycharmProjects/SAAC/venv/lib/python3.7/site-packages/sqlalchemy/sql/elements.py", line 269, in _execute_on_connection
    return connection._execute_clauseelement(self, multiparams, params)
  File "/Users/timc/PycharmProjects/SAAC/venv/lib/python3.7/site-packages/sqlalchemy/engine/base.py", line 1060, in _execute_clauseelement
    compiled_sql, distilled_params
  File "/Users/timc/PycharmProjects/SAAC/venv/lib/python3.7/site-packages/sqlalchemy/engine/base.py", line 1200, in _execute_context
    context)
  File "/Users/timc/PycharmProjects/SAAC/venv/lib/python3.7/site-packages/sqlalchemy/engine/base.py", line 1413, in _handle_dbapi_exception
    exc_info
  File "/Users/timc/PycharmProjects/SAAC/venv/lib/python3.7/site-packages/sqlalchemy/util/compat.py", line 265, in raise_from_cause
    reraise(type(exception), exception, tb=exc_tb, cause=cause)
  File "/Users/timc/PycharmProjects/SAAC/venv/lib/python3.7/site-packages/sqlalchemy/util/compat.py", line 248, in reraise
    raise value.with_traceback(tb)
  File "/Users/timc/PycharmProjects/SAAC/venv/lib/python3.7/site-packages/sqlalchemy/engine/base.py", line 1193, in _execute_context
    context)
  File "/Users/timc/PycharmProjects/SAAC/venv/lib/python3.7/site-packages/sqlalchemy/engine/default.py", line 509, in do_execute
    cursor.execute(statement, parameters)
sqlalchemy.exc.OperationalError: (sqlite3.OperationalError) database is locked [SQL: 'UPDATE request SET is_active=? WHERE request.id = ?'] [parameters: (0, 11)] (Background on this error at: http://sqlalche.me/e/e3q8)
2018-10-13 18:19:26,190 INFO: Microblog startup [in /Users/timc/PycharmProjects/SAAC/app/__init__.py:45]
